<?xml version="1.0" encoding="UTF-8"?>
<testsuite name="SRHPasswordManager_tests.TestNotebook-20240123153820" tests="4" file="SRHPasswordManager_tests.py" time="0.241" timestamp="2024-01-23T15:38:21" failures="1" errors="0" skipped="0">
	<testcase classname="SRHPasswordManager_tests.TestNotebook" name="test_add_entry" time="0.151" timestamp="2024-01-23T15:38:21"/>
	<testcase classname="SRHPasswordManager_tests.TestNotebook" name="test_check_for_file_existing" time="0.002" timestamp="2024-01-23T15:38:21"/>
	<testcase classname="SRHPasswordManager_tests.TestNotebook" name="test_check_for_file_not_existing" time="0.001" timestamp="2024-01-23T15:38:21"/>
	<testcase classname="SRHPasswordManager_tests.TestNotebook" name="test_load_and_decrypt" time="0.087" timestamp="2024-01-23T15:38:21">
		<failure type="AssertionError" message="expected call not found.
Expected: open('Notebook.txt', 'r')
Actual: open('Notebook.txt', 'rb')"><![CDATA[Traceback (most recent call last):
  File "C:\Users\Acer\anaconda3\Lib\unittest\case.py", line 57, in testPartExecutor
    yield
  File "C:\Users\Acer\anaconda3\Lib\unittest\case.py", line 623, in run
    self._callTestMethod(testMethod)
    ^^^^^^^^^^^^^^^^^
  File "C:\Users\Acer\anaconda3\Lib\unittest\case.py", line 579, in _callTestMethod
    if method() is not None:
    ^^^^^^^^^^^^^^^^^
  File "c:\users\acer\documents\github\srhpasswordmanager\src\unittest\python\SRHPasswordManager_tests.py", line 36, in test_load_and_decrypt
    m.assert_called_once_with('Notebook.txt', 'r')
    ^^^^^^^^^^^^^^^^^
  File "C:\Users\Acer\anaconda3\Lib\unittest\mock.py", line 951, in assert_called_once_with
    return self.assert_called_with(*args, **kwargs)
    ^^^^^^^^^^^^^^^^^
  File "C:\Users\Acer\anaconda3\Lib\unittest\mock.py", line 939, in assert_called_with
    raise AssertionError(_error_message()) from cause
    ^^^^^^^^^^^^^^^^^
AssertionError: expected call not found.
Expected: open('Notebook.txt', 'r')
Actual: open('Notebook.txt', 'rb')
]]></failure>
	</testcase>
</testsuite>
